Workbook

Sheet Formulario
A1: Datos Generales
A2: Area Techada (m2) | B2: Area del terreno (m2) | C2: Plazo de ejecución (meses) | D2: Area Techada Escalera (m2)
A5: Opciones Adicionales
A6: INCLUIR DEMOLICIONES | B6: INCLUIR COLUMNETAS Y VIGUETAS DE CONFINAMIENTO
A7: SI | B7: SI
A8: NO | B8: NO
A12: Cimentación
A13: TIPO DE CIMENTACION | B13: Numero de pisos | C13: Área de cimentación (m2)
A14: ZAPATAS Y VIGAS DE CIMENTACION | B14: 1
A15: PLATEA DE CIMENTACIÓN | B15: 2
B16: 3
B17: 4
A24: Ambientes
B25: Cantidad | C25: Area (m2)
A26: BIBLIOTECA
A27: LABORATORIO
A28: ALMACÉN MAT. DEP.
A29: SUM
A30: MÓDULO DE CONECTIVIDAD
A31: DIRECCIÓN ADM.
A32: SUBDIRECCIÓN
A33: SALA DE REUNIONES
A34: SECRETARÍA
A35: ÁREA DE ESPERA
A36: COORDINACIÓN ADMINISTRATIVA
A37: ARCHIVO
... A83: Exteriores
B84: Cantidad | C84: Area
A85: AREAS VERDES | B85: Cantidad | C85: Area
A86: LOSA DEPORTIVA | B86: Cantidad | C86: Area
A87: COBERTURA DE LOSA DEPORTIVA | B87: Cantidad | C87: Area
A88: PATIO DE INICIAL | B88: Cantidad | C88: Area
A89: COBERTURA PATIO DE INICIAL | B89: Cantidad | C89: Area
A90: VEREDAS Y RAMPAS DE CONCRETO | B90: Cantidad | C90: Area
A91: PAVIMENTO RIGIDO VEHICULAR | B91: Cantidad | C91: Area
A92: CERCO PERIMETRICO H=3.00M | B92: Cantidad | C92: Area
A93: Adicionales
A94: ASTA DE BANDERA | B94: Cantidad
A95: ESTACIONAMIENTO DE BICICLETAS | B95: Cantidad
A96: PORTADA DE INGRESO (PORTON METALICO) | B96: Cantidad
...

Sheet Datos iniciales 
A1: Categoría
A2: Obras provisionales | B2: Area Techada | C2: Area del terreno | D2: Plazo de ejecución | E2: Incluye demoliciones | F2: CT
B3: 300 | C3: 1000 | D3: 12 | E3: SI | F3: {=_xlfn.IFS(E3="SI",PROVISIONALES!K3,E3="NO",PROVISIONALES!K3-SUM(PROVISIONALES!J24:J25))} -> 218226.19
A4: Cimentación | B4: Área de cimentación | C4: #pisos | D4: Tipo de cimentacion | E4: Área de cimentación | F4: #pisos | G4: Tipo de cimentacion
B5: 200 | C5: 1 | D5: zapatas y vigas de cimentación | F5: 1 | G5: platea de cimentación
B6: 200 | C6: 2 | D6: zapatas y vigas de cimentación | E6: 100 | F6: 2 | G6: platea de cimentación
B7: 100 | C7: 3 | D7: zapatas y vigas de cimentación | F7: 3 | G7: platea de cimentación
B8: 100 | C8: 4 | D8: zapatas y vigas de cimentación | F8: 4 | G8: platea de cimentación
A10: Estructura | B10: Area Techada | D10: Incluye columnetas y viguetas | E10: Costo x m2 | F10: CT
B11: 300 | D11: SI | E11: {=_xlfn.IFS(D11="NO",'Estructura 1'!M4,D11="SI",'Estructura 1'!M4+'Estructura 2'!M4)} -> 858.86574 | F11: =B11*E11 -> 257659.72
B12: Area Techada escalera | E12: Costo x m2 | F12: CT
B13: 15 | E13: {=_xlfn.IFS(B13=0,0,B13>0,Escalera!N4)} -> 601.62699 | F13: =B13*E13 -> 9024.4049
A14: Ambientes
C15: Area | D15: Total Area
A16: BIBLIOTECA | B16: 2 | C16: 10 | D16: =ROUND(B16*C16,2) -> 20
A17: LABORATORIO | B17: 2 | C17: 10 | D17: =ROUND(B17*C17,2) -> 20
A18: ALMACÉN MAT. DEP. | B18: 2 | C18: 10 | D18: =ROUND(B18*C18,2) -> 20
A19: SUM | B19: 2 | C19: 10 | D19: =ROUND(B19*C19,2) -> 20
A20: MÓDULO DE CONECTIVIDAD | B20: 2 | C20: 10 | D20: =ROUND(B20*C20,2) -> 20
A21: DIRECCIÓN ADM. | B21: 2 | C21: 10 | D21: =ROUND(B21*C21,2) -> 20
A22: SUBDIRECCIÓN | B22: 2 | C22: 10 | D22: =ROUND(B22*C22,2) -> 20
A23: SALA DE REUNIONES | B23: 2 | C23: 10 | D23: =ROUND(B23*C23,2) -> 20
A24: SECRETARÍA | B24: 2 | C24: 10 | D24: =ROUND(B24*C24,2) -> 20
A25: ÁREA DE ESPERA | B25: 2 | C25: 10 | D25: =ROUND(B25*C25,2) -> 20
A26: COORDINACIÓN ADMINISTRATIVA | B26: 2 | C26: 10 | D26: =ROUND(B26*C26,2) -> 20
A27: ARCHIVO | B27: 2 | C27: 10 | D27: =ROUND(B27*C27,2) -> 20
... A68: AREA DE INGRESO | B68: 2 | C68: 10 | D68: =ROUND(B68*C68,2) -> 20
A69: #AMBIENTES | B69: =SUM(B16:B68) -> 106
A71: Exteriores | B71: Cantidad | C71: Area | D71: ML | E71: Area total
A72: AREAS VERDES | B72: 2 | C72: 10 | E72: =ROUND(B72*C72,2) -> 20
A73: LOSA DEPORTIVA | B73: 2 | C73: 10 | E73: =ROUND(B73*C73,2) -> 20
A74: COBERTURA LOSA DEPORTIVA | B74: 2 | C74: 10 | E74: =ROUND(B74*C74,2) -> 20
A75: PATIO DE INICIAL | B75: 2 | C75: 10 | E75: =ROUND(B75*C75,2) -> 20
A76: COBERTURA PATIO DE INICIAL | B76: 2 | C76: 10 | E76: =ROUND(B76*C76,2) -> 20
A77: ASTA DE BANDERA | B77: 2 | E77: =B77 -> 2
A78: VEREDAS Y RAMPAS DE CONCRETO | B78: 2 | C78: 10 | E78: =ROUND(B78*C78,2) -> 20
A79: PAVIMENTO RIGIDO VEHICULAR | B79: 2 | C79: 10 | E79: =ROUND(B79*C79,2) -> 20
A80: LAMAS EN PASADIZOS | B80: 2 | C80: 10 | E80: =ROUND(B80*C80,2) -> 20
A81: ESTACIONAMIENTO DE BICICLETAS | B81: 2 | E81: =B81 -> 2
A82: CERCO PERIMETRICO H=3.00m | B82: 2 | D82: 10 | E82: =ROUND(B82*D82,2) -> 20
...

Sheet RESUMEN
B3: Cant. | C3: meta | D3: Costo | E3: Unidad
A4: BIBLIOTECA | B4: ='Datos iniciales '!B16 -> 2 | C4: ='Datos iniciales '!D16 -> 20 | D4: =ROUND('calculo r'!L4,2) -> 52920.75 | E4: M2
A5: LABORATORIO | B5: ='Datos iniciales '!B17 -> 2 | C5: ='Datos iniciales '!D17 -> 20 | D5: =ROUND('calculo r'!L5,2) -> 60200.07 | E5: M2
A6: ALMACÉN MAT. DEP. | B6: ='Datos iniciales '!B18 -> 2 | C6: ='Datos iniciales '!D18 -> 20 | D6: =ROUND('calculo r'!L6,2) -> 50547.69 | E6: M2
A7: SUM | B7: ='Datos iniciales '!B19 -> 2 | C7: ='Datos iniciales '!D19 -> 20 | D7: =ROUND('calculo r'!L7,2) -> 54280.68 | E7: M2
A8: MÓDULO DE CONECTIVIDAD | B8: ='Datos iniciales '!B20 -> 2 | C8: ='Datos iniciales '!D20 -> 20 | D8: =ROUND('calculo r'!L8,2) -> 58963.68 | E8: M2
A9: DIRECCIÓN ADM. | B9: ='Datos iniciales '!B21 -> 2 | C9: ='Datos iniciales '!D21 -> 20 | D9: =ROUND('calculo r'!L9,2) -> 75790.51 | E9: M2
A10: SUBDIRECCIÓN | B10: ='Datos iniciales '!B22 -> 2 | C10: ='Datos iniciales '!D22 -> 20 | D10: =ROUND('calculo r'!L10,2) -> 75790.51 | E10: M2
A11: SALA DE REUNIONES | B11: ='Datos iniciales '!B23 -> 2 | C11: ='Datos iniciales '!D23 -> 20 | D11: =ROUND('calculo r'!L11,2) -> 61511.16 | E11: M2
A12: SECRETARÍA | B12: ='Datos iniciales '!B24 -> 2 | C12: ='Datos iniciales '!D24 -> 20 | D12: =ROUND('calculo r'!L12,2) -> 58931.23 | E12: M2
A13: ÁREA DE ESPERA | B13: ='Datos iniciales '!B25 -> 2 | C13: ='Datos iniciales '!D25 -> 20 | D13: =ROUND('calculo r'!L13,2) -> 58931.23 | E13: M2
A14: COORDINACIÓN ADMINISTRATIVA | B14: ='Datos iniciales '!B26 -> 2 | C14: ='Datos iniciales '!D26 -> 20 | D14: =ROUND('calculo r'!L14,2) -> 48572.12 | E14: M2
A15: ARCHIVO | B15: ='Datos iniciales '!B27 -> 2 | C15: ='Datos iniciales '!D27 -> 20 | D15: =ROUND('calculo r'!L15,2) -> 71181.3 | E15: M2
... A56: AREA DE INGRESO | B56: ='Datos iniciales '!B68 -> 2 | C56: ='Datos iniciales '!D68 -> 20 | D56: =ROUND('calculo r'!L56,2) -> 34994.74 | E56: M2
A57: EXTERIORES
A58: AREAS VERDES | B58: ='Datos iniciales '!B72 -> 2 | C58: ='Datos iniciales '!C72 -> 10 | D58: =ROUND('calculo r'!L58,2) -> 9520.08 | E58: M2
A59: LOSA DEPORTIVA | B59: ='Datos iniciales '!B73 -> 2 | C59: ='Datos iniciales '!C73 -> 10 | D59: =ROUND('calculo r'!L59,2) -> 10610.77 | E59: M2
A60: COBERTURA LOSA DEPORTIVA | B60: ='Datos iniciales '!B74 -> 2 | C60: ='Datos iniciales '!C74 -> 10 | D60: =ROUND('calculo r'!L60,2) -> 3389.8 | E60: M2
A61: PATIO DE INICIAL | B61: ='Datos iniciales '!B75 -> 2 | C61: ='Datos iniciales '!C75 -> 10 | D61: =ROUND('calculo r'!L61,2) -> 10610.77 | E61: M2
A62: COBERTURA PATIO DE INICIAL | B62: ='Datos iniciales '!B76 -> 2 | C62: ='Datos iniciales '!C76 -> 10 | D62: =ROUND('calculo r'!L62,2) -> 3389.8 | E62: M2
A63: VEREDAS Y RAMPAS DE CONCRETO | B63: ='Datos iniciales '!B78 -> 2 | C63: ='Datos iniciales '!C78 -> 10 | D63: =ROUND('calculo r'!L64,2) -> 10084.8 | E63: M2
A64: PAVIMENTO RIGIDO VEHICULAR | B64: ='Datos iniciales '!B79 -> 2 | C64: ='Datos iniciales '!C79 -> 10 | D64: =ROUND('calculo r'!L65,2) -> 10786.91 | E64: M2
A65: CERCO PERIMETRICO H=3.00m | B65: ='Datos iniciales '!B82 -> 2 | C65: ='Datos iniciales '!C82 -> 0 | D65: =ROUND('calculo r'!L68,2) -> 70735.58 | E65: ML
A66: Adicionales
A67: ASTA DE BANDERA | B67: ='Datos iniciales '!B77 -> 2 | C67: ='Datos iniciales '!C77 -> 0 | D67: =ROUND('calculo r'!L63,2) -> 4225.7 | E67: UND
A68: LAMAS EN PASADIZOS | B68: ='Datos iniciales '!B80 -> 2 | C68: ='Datos iniciales '!C80 -> 10 | D68: =ROUND('calculo r'!L66,2) -> 1509.2 | E68: M2
A69: ESTACIONAMIENTO DE BICICLETAS | B69: ='Datos iniciales '!B81 -> 2 | C69: ='Datos iniciales '!C81 -> 0 | D69: =ROUND('calculo r'!L67,2) -> 138.82 | E69: UND
A70: PORTADA DE INGRESO (PORTON METALICO) | B70: ='Datos iniciales '!B83 -> 2 | C70: ='Datos iniciales '!C83 -> 0 | D70: =ROUND('calculo r'!L69,2) -> 59161.18 | E70: UND

Sheet PROVISIONALES
G2: Unidad | H2: Metrado | I2: C.U | J2: Parcial | K2: Total
A3: 1 | B3: OBRAS PROVISIONALES, PRELIMINARES, SEGURIDAD Y SALUD EN EL TRABAJO Y PLAN DE CONTINGENCIA | K3: =J4+J19+J29+J38+J66 -> 218226.19
A4: 1.1 | B4: OBRAS PROVISIONALES | J4: =J5+J14 -> 41975.92
A5: 1.1.1 | B5: CONSTRUCCIONES PROVISIONALES | J5: =SUM(J6:J13) -> 36286.56
A6: 1.1.1.1 | B6: OFICINAS DE RESIDENCIA Y SUPERVISIÓN | G6: m2 | H6: =ROUND('Obras provisionales'!H9,2) -> 50 | I6: =ROUND('APU PROVISIONALES'!J3,2) -> 158.9 | J6: =ROUND(H6*I6,2) -> 7945
A7: 1.1.1.2 | B7: ALMACENES DE OBRA | G7: m2 | H7: =ROUND('Obras provisionales'!H10,2) -> 3 | I7: =ROUND('APU PROVISIONALES'!J28,2) -> 144.65 | J7: =ROUND(H7*I7,2) -> 433.95
A8: 1.1.1.3 | B8: CASETAS DE GUARDIANÍA | G8: m2 | H8: =ROUND('Obras provisionales'!H11,2) -> 8 | I8: =ROUND('APU PROVISIONALES'!J52,2) -> 148.04 | J8: =ROUND(H8*I8,2) -> 1184.32
A9: 1.1.1.4 | B9: COMEDOR PARA PERSONAL DE OBRA | G9: m2 | H9: =ROUND('Obras provisionales'!H12,2) -> 50 | I9: =ROUND('APU PROVISIONALES'!J76,2) -> 152.57 | J9: =ROUND(H9*I9,2) -> 7628.5
A10: 1.1.1.5 | B10: VESTUARIO PARA PERSONAL DE OBRA | G10: m2 | H10: =ROUND('Obras provisionales'!H13,2) -> 25 | I10: =ROUND('APU PROVISIONALES'!J100,2) -> 206.2 | J10: =ROUND(H10*I10,2) -> 5155
A11: 1.1.1.6 | B11: CERCO PERIMÉTRICO DE MALLA ARPILLERA | G11: m | H11: =ROUND('Obras provisionales'!H14,2) -> 126.49 | I11: =ROUND('APU PROVISIONALES'!J124,2) -> 43.81 | J11: =ROUND(H11*I11,2) -> 5541.53
A12: 1.1.1.7 | B12: SERVICIOS HIGIÉNICOS | G12: m2 | H12: =ROUND('Obras provisionales'!H15,2) -> 16 | I12: =ROUND('APU PROVISIONALES'!J140,2) -> 343.17 | J12: =ROUND(H12*I12,2) -> 5490.72
A13: 1.1.1.8 | B13: CARTEL DE IDENTIFICACIÓN DE LA OBRA | G13: und | H13: =ROUND('Obras provisionales'!H16,2) -> 2 | I13: =ROUND('APU PROVISIONALES'!J170,2) -> 1453.77 | J13: =ROUND(H13*I13,2) -> 2907.54
A14: 1.1.2 | B14: INSTALACIONES PROVISIONALES | J14: =SUM(J15:J18) -> 5689.36
A15: 1.1.2.1 | B15: CONEXIÓN E INSTALACIÓN DE AGUA | G15: glb | H15: =ROUND('Obras provisionales'!H18,2) -> 1 | I15: =ROUND('APU PROVISIONALES'!J193,2) -> 251.61 | J15: =ROUND(H15*I15,2) -> 251.61
A16: 1.1.2.2 | B16: CONSUMO Y MANTENIMIENTO DE AGUA PARA LA CONSTRUCCIÓN | G16: mes | H16: =ROUND('Obras provisionales'!H19,2) -> 12 | I16: =ROUND('APU PROVISIONALES'!J200,2) -> 185.89 | J16: =ROUND(H16*I16,2) -> 2230.68
A17: 1.1.2.3 | B17: CONEXIÓN E INSTALACIÓN DE ENERGÍA ELÉCTRICA | G17: glb | H17: =ROUND('Obras provisionales'!H20,2) -> 1 | I17: =ROUND('APU PROVISIONALES'!J207,2) -> 976.39 | J17: =ROUND(H17*I17,2) -> 976.39
A18: 1.1.2.4 | B18: CONSUMO Y MANTENIMIENTO DE ENERGÍA ELÉCTRICA | G18: mes | H18: =ROUND('Obras provisionales'!H21,2) -> 12 | I18: =ROUND('APU PROVISIONALES'!J214,2) -> 185.89 | J18: =ROUND(H18*I18,2) -> 2230.68
A19: 1.2 | B19: TRABAJOS PRELIMINARES | J19: =J20+J23+J26 -> 19481.2
A20: 1.2.1 | B20: LIMPIEZA DEL TERRENO | J20: =SUM(J21:J22) -> 2490
A21: 1.2.1.1 | B21: LIMPIEZA DEL TERRENO MANUAL | G21: m2 | H21: =ROUND('Obras provisionales'!H27,2) -> 1000 | I21: =ROUND('APU PROVISIONALES'!J221,2) -> 1.14 | J21: =ROUND(H21*I21,2) -> 1140
A22: 1.2.1.2 | B22: ELIMINACIÓN DE OBSTRUCCIONES | G22: m2 | H22: =ROUND('Obras provisionales'!H28,2) -> 1000 | I22: =ROUND('APU PROVISIONALES'!J231,2) -> 1.35 | J22: =ROUND(H22*I22,2) -> 1350
A23: 1.2.2 | B23: MOVILIZACIÓN DE CAMPAMENTO, MAQUINARIA Y HERRAMIENTAS | J23: =SUM(J24:J25) -> 8731.2
A24: 1.2.2.1 | B24: MOVILIZACIÓN DE EQUIPOS Y HERRAMIENTAS | G24: glb | H24: =ROUND('Obras provisionales'!H30,2) -> 1 | I24: =ROUND('APU PROVISIONALES'!J242,2) -> 1746.24 | J24: =ROUND(H24*I24,2) -> 1746.24
A25: 1.2.2.2 | B25: TRANSPORTE DE MATERIALES A LA OBRA | G25: glb | H25: =ROUND('Obras provisionales'!H31,2) -> 1 | I25: =ROUND('APU PROVISIONALES'!J253,2) -> 6984.96 | J25: =ROUND(H25*I25,2) -> 6984.96
A26: 1.2.3 | B26: TRAZOS, NIVELES Y REPLANTEO | J26: =SUM(J27:J28) -> 8260
A27: 1.2.3.1 | B27: TRAZO Y REPLANTEO PRELIMINAR | G27: m2 | H27: =ROUND('Obras provisionales'!H33,2) -> 1000 | I27: =ROUND('APU PROVISIONALES'!J256,2) -> 3.99 | J27: =ROUND(H27*I27,2) -> 3990
A28: 1.2.3.2 | B28: TRAZO NIVELACIÓN Y REPLANTEO DURANTE EL PROCESO | G28: m2 | H28: =ROUND('Obras provisionales'!H34,2) -> 1000 | I28: =ROUND('APU PROVISIONALES'!J276,2) -> 4.27 | J28: =ROUND(H28*I28,2) -> 4270
A29: 1.3 | B29: PLAN DE SEGURIDAD Y SALUD EN EL TRABAJO | J29: =J30 -> 108478.24
A30: 1.3.1 | B30: Equipo de seguridad y salud | J30: =SUM(J31:J37) -> 108478.24
A31: 1.3.1.1 | B31: EQUIPOS DE PROTECCIÓN INDIVIDUAL | G31: glb | H31: =ROUND('Obras provisionales'!H37,2) -> 1 | I31: =ROUND('APU PROVISIONALES'!J295,2) -> 41043.35 | J31: =ROUND(H31*I31,2) -> 41043.35
A32: 1.3.1.2 | B32: EQUIPOS DE PROTECCIÓN COLECTIVA | G32: glb | H32: =ROUND('Obras provisionales'!H38,2) -> 1 | I32: =ROUND('APU PROVISIONALES'!J321,2) -> 3824.87 | J32: =ROUND(H32*I32,2) -> 3824.87
A33: 1.3.1.3 | B33: SEÑALIZACIÓN TEMPORAL DE SEGURIDAD | G33: glb | H33: =ROUND('Obras provisionales'!H39,2) -> 1 | I33: =ROUND('APU PROVISIONALES'!J333,2) -> 6076.5 | J33: =ROUND(H33*I33,2) -> 6076.5
A34: 1.3.1.4 | B34: PROGRAMA DE CAPACITACIÓN EN SEGURIDAD Y SALUD | G34: glb | H34: =ROUND('Obras provisionales'!H40,2) -> 1 | I34: =ROUND('APU PROVISIONALES'!J347,2) -> 18386.64 | J34: =ROUND(H34*I34,2) -> 18386.64
A35: 1.3.1.5 | B35: RECURSOS PARA RESPUESTA ANTE EMERGENCIAS | G35: glb | H35: =ROUND('Obras provisionales'!H41,2) -> 1 | I35: =ROUND('APU PROVISIONALES'!J356,2) -> 1478.8 | J35: =ROUND(H35*I35,2) -> 1478.8
A36: 1.3.1.6 | B36: PROGRAMA DE PREVENCIÓN Y CONTROL | G36: und | H36: =ROUND('Obras provisionales'!H42,2) -> 1 | I36: =ROUND('APU PROVISIONALES'!J368,2) -> 8515.8 | J36: =ROUND(H36*I36,2) -> 8515.8
A37: 1.3.1.7 | B37: EXAMEN MÉDICO GENERAL | G37: und | H37: =ROUND('Obras provisionales'!H43,2) -> 1 | I37: =ROUND('APU PROVISIONALES'!J376,2) -> 29152.28 | J37: =ROUND(H37*I37,2) -> 29152.28
A38: 1.4 | B38: PLAN DE MANEJO AMBIENTAL | J38: =J39+J42+J44+J46+J59+J61 -> 45872.44
A39: 1.4.1 | B39: PROGRAMA DE PREVENCIÓN Y MITIGACIÓN AMBIENTAL | J39: =SUM(J40:J41) -> 21696.42
A40: 1.4.1.1 | B40: PREVENCIÓN Y MITIGACIÓN DE IMPACTOS | G40: m3 | H40: =ROUND('Obras provisionales'!H46,2) -> 609.6 | I40: =ROUND('APU PROVISIONALES'!J384,2) -> 32.56 | J40: =ROUND(H40*I40,2) -> 19848.58
A41: 1.4.1.2 | B41: IMPLEMENTACIÓN DE ÁREA DE SEÑALIZACIÓN | G41: und | H41: =ROUND('Obras provisionales'!H47,2) -> 16 | I41: =ROUND('APU PROVISIONALES'!J397,2) -> 115.49 | J41: =ROUND(H41*I41,2) -> 1847.84
...

Sheet APU PROVISIONALES
A2: Partida | B2: =PROVISIONALES!A6 -> 1.1.1.1 | C2: OFICINAS DE RESIDENCIA Y SUPERVISIÓN
A3: Rendimiento m2/día | B3: m2/dia | C3: M.O | D3: 25 | E3: EQ | F3: =D3 -> 25 | G3: Costo unitario directo | I3: und | J3: =J10++J22+J25 -> 158.9
A4: Código | B4: Descripción Recurso | F4: Unidad | G4: Cuadrilla | H4: Cantidad | I4: Precio (S/.) | J4: Parcial (S/.)
B5: Mano de Obra
B7: OPERARIO | F7: hh | G7: 1 | H7: =ROUND(G7*8/$D$3,4) -> 0.32 | I7: 28.94 | J7: =ROUND(H7*I7,2) -> 9.26 | K7: 47
B8: OFICIAL | F8: hh | G8: 1 | H8: =ROUND(G8*8/$D$3,4) -> 0.32 | I8: 22.66 | J8: =ROUND(H8*I8,2) -> 7.25 | K8: 47
B9: PEON | F9: hh | G9: 3 | H9: =ROUND(G9*8/$D$3,4) -> 0.96 | I9: 20.51 | J9: =ROUND(H9*I9,2) -> 19.69 | K9: 47
J10: =ROUND(SUM(J6:J9),2) -> 36.2
B11: Materiales
B12: ALAMBRE NEGRO RECOCIDO BWG N 16 | F12: kg | H12: 1.25 | I12: 2.64 | J12: =ROUND(H12*I12,2) -> 3.3 | K12: 2
B13: CALAMINA | F13: pln | H13: 1.8 | I13: 14.15 | J13: =ROUND(H13*I13,2) -> 25.47 | K13: 56
B14: CERRADURA CLÁSICA ADOSADA BK 233 | F14: und | H14: 0.2 | I14: 55 | J14: =ROUND(H14*I14,2) -> 11 | K14: 26
B15: CLAVOS PARA CALAMINA | F15: kg | H15: 0.06 | I15: 10.93 | J15: =ROUND(H15*I15,2) -> 0.66 | K15: 2
B16: CLAVO C/CABEZA P/CONSTRUCCION D.PROMEDIO | F16: kg | H16: 0.071 | I16: 5.51 | J16: =ROUND(H16*I16,2) -> 0.39 | K16: 2
B17: HORMIGON | F17: m3 | H17: 0.19 | I17: 70.92 | J17: =ROUND(H17*I17,2) -> 13.47 | K17: 38
B18: TRIPLAY ENCHAPE CEDRO 4' x 8' x 4mm | F18: pln | H18: 0.53 | I18: 27.88 | J18: =ROUND(H18*I18,2) -> 14.78 | K18: 44
B19: VIDRIO CLARO 4MM | F19: p2 | H19: 0.2374 | I19: 32.2 | J19: =ROUND(H19*I19,2) -> 7.64 | K19: 30
B20: CEMENTO PORTLAND TIPO I (42.5 kg) | F20: bls | H20: 1.092 | I20: 24.52 | J20: =ROUND(H20*I20,2) -> 26.78 | K20: 21
B21: MADERA TORNILLO | F21: p2 | H21: 3 | I21: 5.8 | J21: =ROUND(H21*I21,2) -> 17.4 | K21: 43
J22: =ROUND(SUM(J12:J21),2) -> 120.89
B23: Equipos
B24: HERRAMIENTAS MANUALES | F24: %mo | H24: 5 | I24: =ROUND(J10,2) -> 36.2 | J24: =ROUND(H24%*I24,2) -> 1.81 | K24: 37
J25: =ROUND(SUM(J24),2) -> 1.81
A27: Partida | B27: =PROVISIONALES!A7 -> 1.1.1.2 | C27: ALMACENES DE OBRA
A28: Rendimiento m2/día | B28: m2/dia | C28: M.O | D28: 40 | E28: EQ | F28: =D28 -> 40 | G28: Costo unitario directo | I28: und | J28: =J34++J46+J49 -> 144.65
A29: Código | B29: Descripción Recurso | F29: Unidad | G29: Cuadrilla | H29: Cantidad | I29: Precio (S/.) | J29: Parcial (S/.)
B30: Mano de Obra
B31: OPERARIO | F31: hh | G31: 1 | H31: =ROUND(G31*8/$D$28,4) -> 0.2 | I31: 28.94 | J31: =ROUND(H31*I31,2) -> 5.79 | K31: 47
B32: OFICIAL | F32: hh | G32: 1 | H32: =ROUND(G32*8/$D$28,4) -> 0.2 | I32: 22.66 | J32: =ROUND(H32*I32,2) -> 4.53 | K32: 47
B33: PEON | F33: hh | G33: 3 | H33: =ROUND(G33*8/$D$28,4) -> 0.6 | I33: 20.51 | J33: =ROUND(H33*I33,2) -> 12.31 | K33: 47
J34: =ROUND(SUM(J31:J33),2) -> 22.63
B35: Materiales
B36: ALAMBRE NEGRO RECOCIDO BWG N 16 | F36: kg | H36: 1.25 | I36: 2.64 | J36: =ROUND(H36*I36,2) -> 3.3 | K36: 2
B37: CALAMINA | F37: pln | H37: 1.8 | I37: 14.15 | J37: =ROUND(H37*I37,2) -> 25.47 | K37: 56
B38: CERRADURA CLÁSICA ADOSADA BK 233 | F38: und | H38: 0.2 | I38: 55 | J38: =ROUND(H38*I38,2) -> 11 | K38: 26
B39: CLAVOS PARA CALAMINA | F39: kg | H39: 0.06 | I39: 10.93 | J39: =ROUND(H39*I39,2) -> 0.66 | K39: 2
B40: CLAVO C/CABEZA P/CONSTRUCCION D.PROMEDIO | F40: kg | H40: 0.071 | I40: 5.51 | J40: =ROUND(H40*I40,2) -> 0.39 | K40: 2
B41: HORMIGON | F41: m3 | H41: 0.19 | I41: 70.92 | J41: =ROUND(H41*I41,2) -> 13.47 | K41: 38
B42: TRIPLAY ENCHAPE CEDRO 4' x 8' x 4mm | F42: pln | H42: 0.53 | I42: 27.88 | J42: =ROUND(H42*I42,2) -> 14.78 | K42: 44
B43: VIDRIO CLARO 4MM | F43: p2 | H43: 0.2374 | I43: 32.2 | J43: =ROUND(H43*I43,2) -> 7.64 | K43: 30
...

Sheet ESTRUCTURA
G2: Unidad | H2: Metrado | I2: C.U | J2: Parcial | K2: Total
A3: 2 | B3: ESTRUCTURA | K3: =J4+J14+J23+J72 -> 1179659.2
A4: 2.01 | B4: MOVIMIENTO DE TIERRAS | J4: =SUM(J5:J13) -> 138561.14
A5: 02.01.01 | B5: EXCAVACIÓN LOCALIZADA CON MAQUINARIA | G5: m3 | H5: =ROUND('Cimentación 1 piso'!H9+'Cimentación 2 pisos '!H9+'Cimentación 3 pisos'!H9+'Cimentación 4 pisos'!H9+'Platea de Cimentacion'!H9,2) -> 2961.86 | I5: =ROUND('APU ESTRUCTURAS'!J2,2) -> 8.46 | J5: =ROUND(H5*I5,2) -> 25057.34
A6: 02.01.02 | B6: EXCAVACIÓN MANUAL | G6: m3 | H6: =ROUND('Cimentación 1 piso'!H10+'Cimentación 2 pisos '!H10+'Cimentación 3 pisos'!H10+'Cimentación 4 pisos'!H10+'Platea de Cimentacion'!H10,2) -> 38.29 | I6: =ROUND('APU ESTRUCTURAS'!J18,2) -> 49.41 | J6: =ROUND(H6*I6,2) -> 1891.91
A7: 02.01.03 | B7: RELLENO COMPACTADO C/PLANCHA COMPACTADORA C/MATERIAL DE PRÉSTAMO | G7: m3 | H7: =ROUND('Cimentación 1 piso'!H11+'Cimentación 2 pisos '!H11+'Cimentación 3 pisos'!H11+'Cimentación 4 pisos'!H11+'Platea de Cimentacion'!H11,2) -> 176.72 | I7: =ROUND('APU ESTRUCTURAS'!J29,2) -> 66.23 | J7: =ROUND(H7*I7,2) -> 11704.17
A8: 02.01.04 | B8: RELLENO COMPACTADO C/PLANCHA COMPACTADORA C/MATERIAL PROPIO | G8: m3 | H8: =ROUND('Cimentación 1 piso'!H12+'Cimentación 2 pisos '!H12+'Cimentación 3 pisos'!H12+'Cimentación 4 pisos'!H12+'Platea de Cimentacion'!H12,2) -> 1827.84 | I8: =ROUND('APU ESTRUCTURAS'!J46,2) -> 19.77 | J8: =ROUND(H8*I8,2) -> 36136.4
A9: 02.01.05 | B9: FORMACION Y COMPACTACION DE SUBRASANTE | G9: m2 | H9: =ROUND('Cimentación 1 piso'!H13+'Cimentación 2 pisos '!H13+'Cimentación 3 pisos'!H13+'Cimentación 4 pisos'!H13+'Platea de Cimentacion'!H13,2) -> 1332.21 | I9: =ROUND('APU ESTRUCTURAS'!J63,2) -> 7.99 | J9: =ROUND(H9*I9,2) -> 10644.36
A10: 02.01.06 | B10: ACARREO DE MATERIAL EXCEDENTE | G10: m2 | H10: =ROUND('Cimentación 1 piso'!H14+'Cimentación 2 pisos '!H14+'Cimentación 3 pisos'!H14+'Cimentación 4 pisos'!H14+'Platea de Cimentacion'!H14,2) -> 1446.64 | I10: =ROUND('APU ESTRUCTURAS'!J78,2) -> 12.11 | J10: =ROUND(H10*I10,2) -> 17518.81
A11: 02.01.07 | B11: ELIMINACIÓN DE MATERIAL EXCEDENTE HASTA D=10 KM | G11: m3 | H11: =ROUND('Cimentación 1 piso'!H15+'Cimentación 2 pisos '!H15+'Cimentación 3 pisos'!H15+'Cimentación 4 pisos'!H15+'Platea de Cimentacion'!H15,2) -> 1446.64 | I11: =ROUND('APU ESTRUCTURAS'!J89,2) -> 22.88 | J11: =ROUND(H11*I11,2) -> 33099.12
A12: 02.01.08 | B12: COMPACTACION DE SUBRASANTE LOSA DEPORTIVA | G12: m3 | H12: =ROUND('Obras exteriores '!D11+'Obras exteriores '!D27+'Obras exteriores '!D45,2) -> 60 | I12: =ROUND('APU ESTRUCTURAS'!J102,2) -> 7.99 | J12: =ROUND(H12*I12,2) -> 479.4
A13: 02.01.09 | B13: AFIRMADO DE e=0.30m PARA LOSA DEPORTIVA | G13: m3 | H13: =ROUND('Obras exteriores '!D12+'Obras exteriores '!D28+'Obras exteriores '!D46+'Obras exteriores '!D59,2) -> 26.4 | I13: =ROUND('APU ESTRUCTURAS'!J117,2) -> 76.88 | J13: =ROUND(H13*I13,2) -> 2029.63
A14: 2.02 | B14: CONCRETO SIMPLE | J14: =J15+J17+J19+J21 -> 177094.62
A15: 02.02.01 | B15: CONCRETO CICLOPEO -PLATEA DE CIMENTACION | J15: =SUM(J16) -> 23735
A16: 02.02.01.01 | B16: CONCRETO CICLOPEO F’C=100 KG/CM² + PIEDRA GRANDE DE 8" E=0.80 M | G16: m2 | H16: =ROUND('Platea de Cimentacion'!H17,2) -> 100 | I16: =ROUND('APU ESTRUCTURAS'!J139,2) -> 237.35 | J16: =ROUND(H16*I16,2) -> 23735
A17: 02.02.02 | B17: FALSA ZAPATA | J17: =SUM(J18) -> 132037.81
A18: 02.02.02.01 | B18: FALSA ZAPATA F’C=100 KG/CM² + PIEDRA GRANDE DE 8" E=0.80 M | G18: m2 | H18: =ROUND('Cimentación 1 piso'!H17+'Cimentación 2 pisos '!H17+'Cimentación 3 pisos'!H17+'Cimentación 4 pisos'!H17+Escalera!D7,2) -> 556.3 | I18: =ROUND('APU ESTRUCTURAS'!J161,2) -> 237.35 | J18: =ROUND(H18*I18,2) -> 132037.81
A19: 02.02.03 | B19: FALSO PISO | J19: =SUM(J20) -> 20540.99
A20: 02.02.03.01 | B20: FALSO PISO E = 4" FC = 175 KG/CM2 | G20: m2 | H20: =ROUND('Cimentación 1 piso'!H19+'Cimentación 2 pisos '!H19+'Cimentación 3 pisos'!H19+'Cimentación 4 pisos'!H19+Escalera!D8,2) -> 524.54 | I20: =ROUND('APU ESTRUCTURAS'!J183,2) -> 39.16 | J20: =ROUND(H20*I20,2) -> 20540.99
A21: 02.02.04 | B21: SOLADOS | J21: =SUM(J22) -> 780.82
A22: 02.02.04.01 | B22: SOLADO PARA VIGA DE CIMENTACIÓN FC=100 KG/CM2 E=4" | G22: m2 | H22: =ROUND('Cimentación 1 piso'!H21+'Cimentación 2 pisos '!H21+'Cimentación 3 pisos'!H21+'Cimentación 4 pisos'!H21,2) -> 29.31 | I22: =ROUND('APU ESTRUCTURAS'!J202,2) -> 26.64 | J22: =ROUND(H22*I22,2) -> 780.82
A23: 2.03 | B23: CONCRETO ARMADO | J23: =J24+J27+J31+J35+J39+J43+J47+J51+J55+J60+J64+J68 -> 732208.41
A24: 02.03.01 | B24: ZAPATAS | J24: =SUM(J25:J26) -> 219679.09
A25: 02.03.01.01 | B25: ZAPATAS.- CONCRETO f'c=210 Kg/cm2 | G25: m3 | H25: =ROUND('Cimentación 1 piso'!H24+'Cimentación 2 pisos '!H24+'Cimentación 3 pisos'!H24+'Cimentación 4 pisos'!H24,2) -> 355.99 | I25: =ROUND('APU ESTRUCTURAS'!J221,2) -> 424.08 | J25: =ROUND(H25*I25,2) -> 150968.24
A26: 02.03.01.02 | B26: ZAPATAS.- ACERO DE REFUERZO fy=4,200 Kg/cm2 | G26: kg | H26: =ROUND('Cimentación 1 piso'!H25+'Cimentación 2 pisos '!H25+'Cimentación 3 pisos'!H25+'Cimentación 4 pisos'!H25,2) -> 12402.68 | I26: =ROUND('APU ESTRUCTURAS'!J244,2) -> 5.54 | J26: =ROUND(H26*I26,2) -> 68710.85
A27: 02.03.02 | B27: PLATEA DE CIMENTACION | J27: =SUM(J28:J30) -> 108928.3
A28: 02.03.02.01 | B28: PLATEA DE CIMENTACION. – CONCRETO f'c=210 | G28: m3 | H28: =ROUND('Platea de Cimentacion'!H24,2) -> 60 | I28: =ROUND('APU ESTRUCTURAS'!J260,2) -> 424.08 | J28: =ROUND(H28*I28,2) -> 25444.8
A29: 02.03.02.02 | B29: PLATEA DE CIMENTACION. – ENCOFRADO Y DESENCOFRADO | G29: m2 | H29: =ROUND('Platea de Cimentacion'!H25,2) -> 50 | I29: =ROUND('APU ESTRUCTURAS'!J282,2) -> 74.15 | J29: =ROUND(H29*I29,2) -> 3707.5
A30: 02.03.02.03 | B30: PLATEA DE CIMENTACION.- ACERO DE REFUERZO fy=4,200 Kg/cm2 | G30: kg | H30: =ROUND('Platea de Cimentacion'!H26,2) -> 14400 | I30: =ROUND('APU ESTRUCTURAS'!J298,2) -> 5.54 | J30: =ROUND(H30*I30,2) -> 79776
A31: 02.03.03 | B31: SOBRECIMIENTOS ARMADO | J31: =SUM(J32:J34) -> 85022.38
A32: 02.03.03.01 | B32: SOBRECIMIENTO REFORZADO.- CONCRETO 210 KG/CM2 | G32: m3 | H32: =ROUND('Cimentación 1 piso'!H27+'Cimentación 2 pisos '!H27+'Cimentación 3 pisos'!H27+'Cimentación 4 pisos'!H27+'Platea de Cimentacion'!H28,2) -> 80.78 | I32: =ROUND('APU ESTRUCTURAS'!J314,2) -> 435.71 | J32: =ROUND(H32*I32,2) -> 35196.65
A33: 02.03.03.02 | B33: SOBRECIMIENTOS REFORZADOS.- ENCOFRADO Y DESENCOFRADO | G33: m2 | H33: =ROUND('Cimentación 1 piso'!H28+'Cimentación 2 pisos '!H28+'Cimentación 3 pisos'!H28+'Cimentación 4 pisos'!H28+'Platea de Cimentacion'!H29,2) -> 443.33 | I33: =ROUND('APU ESTRUCTURAS'!J336,2) -> 63.25 | J33: =ROUND(H33*I33,2) -> 28040.62
A34: 02.03.03.03 | B34: SOBRECIMIENTO ARMADO.- ACERO DE REFUERZO fy=4,200 Kg/cm2 | G34: kg | H34: =ROUND('Cimentación 1 piso'!H29+'Cimentación 2 pisos '!H29+'Cimentación 3 pisos'!H29+'Cimentación 4 pisos'!H29+'Platea de Cimentacion'!H30,2) -> 3932.33 | I34: =ROUND('APU ESTRUCTURAS'!J352,2) -> 5.54 | J34: =ROUND(H34*I34,2) -> 21785.11
A35: 02.03.04 | B35: VIGAS DE CIMENTACIÓN | J35: =SUM(J36:J38) -> 53867.06
A36: 02.03.04.01 | B36: VIGAS DE CIMENTACIÓN.- CONCRETO 210 KG/CM2 | G36: m3 | H36: =ROUND('Cimentación 1 piso'!H31+'Cimentación 2 pisos '!H31+'Cimentación 3 pisos'!H31+'Cimentación 4 pisos'!H31+Escalera!D11,2) -> 45.93 | I36: =ROUND('APU ESTRUCTURAS'!J370,2) -> 421.12 | J36: =ROUND(H36*I36,2) -> 19342.04
A37: 02.03.04.02 | B37: VIGAS DE CIMENTACIÓN.- ENCOFRADO Y DESENCOFRADO | G37: m2 | H37: =ROUND('Cimentación 1 piso'!H32+'Cimentación 2 pisos '!H32+'Cimentación 3 pisos'!H32+'Cimentación 4 pisos'!H32+Escalera!D12,2) -> 234.31 | I37: =ROUND('APU ESTRUCTURAS'!J391,2) -> 42.26 | J37: =ROUND(H37*I37,2) -> 9901.94
A38: 02.03.04.03 | B38: VIGAS DE CIMENTACIÓN.- ACERO DE REFUERZO fy=4,200 Kg/cm2 | G38: kg | H38: =ROUND('Cimentación 1 piso'!H33+'Cimentación 2 pisos '!H33+'Cimentación 3 pisos'!H33+'Cimentación 4 pisos'!H33+Escalera!D13,2) -> 4444.6 | I38: =ROUND('APU ESTRUCTURAS'!J407,2) -> 5.54 | J38: =ROUND(H38*I38,2) -> 24623.08
A39: 02.03.05 | B39: COLUMNAS | J39: =SUM(J40:J42) -> 80734.44
A40: 02.03.05.01 | B40: COLUMNAS-CONCRETO fc=210kg/cm2 | G40: m3 | H40: =ROUND('Estructura 1'!G6,2) -> 48.04 | I40: =ROUND('APU ESTRUCTURAS'!J423,2) -> 399.77 | J40: =ROUND(H40*I40,2) -> 19204.95
A41: 02.03.05.02 | B41: COLUMNAS.- ENCOFRADO Y DESENCOFRADO | G41: m2 | H41: =ROUND('Estructura 1'!G7,2) -> 349.57 | I41: =ROUND('APU ESTRUCTURAS'!J444,2) -> 46.59 | J41: =ROUND(H41*I41,2) -> 16286.47
...

Sheet APU ESTRUCTURAS
A1: Partida | B1: =ESTRUCTURA!A5 -> 02.01.01 | C1: EXCAVACIÓN LOCALIZADA CON MAQUINARIA
A2: Rendimiento m2/día | B2: m3/dia | C2: M.O | D2: 250 | E2: EQ | F2: =D2 -> 250 | G2: Costo unitario directo | I2: m3 | J2: =J8+J12 -> 8.46
A3: Código | B3: Descripción Recurso | F3: Unidad | G3: Cuadrilla | H3: Cantidad | I3: Precio (S/.) | J3: Parcial (S/.)
B4: Mano de Obra
B5: CAPATAZ | F5: hh | G5: 0.1 | H5: =ROUND(G5*8/$D$2,4) -> 0.0032 | I5: 34.73 | J5: =ROUND(H5*I5,2) -> 0.11 | K5: 47
B6: OPERARIO | F6: hh | G6: 2 | H6: =ROUND(G6*8/$D$2,4) -> 0.064 | I6: 28.94 | J6: =ROUND(H6*I6,2) -> 1.85 | K6: 47
B7: PEON | F7: hh | G7: 1 | H7: =ROUND(G7*8/$D$2,4) -> 0.032 | I7: 20.51 | J7: =ROUND(H7*I7,2) -> 0.66 | K7: 47
J8: =ROUND(SUM(J5:J7),2) -> 2.62
B9: Equipos
B10: HERRAMIENTAS MANUALES | F10: %mo | H10: 3 | I10: =ROUND(J8,2) -> 2.62 | J10: =ROUND(H10%*I10,2) -> 0.08 | K10: 37
B11: RETROEXCAVADORA SOBRE LLANTAS 58 HP 1YD3 | F11: hm | G11: 1 | H11: =ROUND(G11*8/$D$2,4) -> 0.032 | I11: 180 | J11: =ROUND(H11*I11,2) -> 5.76 | K11: 49
J12: =ROUND(SUM(J10:J11),2) -> 5.84
A17: Partida | B17: =ESTRUCTURA!A6 -> 02.01.02 | C17: EXCAVACIÓN MANUAL
A18: Rendimiento m2/día | B18: m3/dia | C18: M.O | D18: 4 | E18: EQ | F18: =D18 -> 4 | G18: Costo unitario directo | I18: m3 | J18: =J23+J26 -> 49.41
A19: Código | B19: Descripción Recurso | F19: Unidad | G19: Cuadrilla | H19: Cantidad | I19: Precio (S/.) | J19: Parcial (S/.)
B20: Mano de Obra
B21: CAPATAZ | F21: hh | G21: 0.1 | H21: =ROUND(G21*8/$D$18,4) -> 0.2 | I21: 34.73 | J21: =ROUND(H21*I21,2) -> 6.95 | K21: 47
B22: PEON | F22: hh | G22: 1 | H22: =ROUND(G22*8/$D$18,4) -> 2 | I22: 20.51 | J22: =ROUND(H22*I22,2) -> 41.02 | K22: 47
J23: =ROUND(SUM(J21:J22),2) -> 47.97
B24: Equipos
B25: HERRAMIENTAS MANUALES | F25: %mo | H25: 3 | I25: =J23 -> 47.97 | J25: =ROUND(H25%*I25,2) -> 1.44 | K25: 37
J26: =ROUND(SUM(J25),2) -> 1.44
A28: Partida | B28: =ESTRUCTURA!A7 -> 02.01.03 | C28: RELLENO COMPACTADO C/PLANCHA COMPACTADORA C/MATERIAL DE PRÉSTAMO
A29: Rendimiento m2/día | B29: m3/dia | C29: M.O | D29: 30 | E29: EQ | F29: =D29 -> 30 | G29: Costo unitario directo | I29: m3 | J29: =J35+J39+J43 -> 66.23
A30: Código | B30: Descripción Recurso | F30: Unidad | G30: Cuadrilla | H30: Cantidad | I30: Precio (S/.) | J30: Parcial (S/.)
B31: Mano de Obra
B32: CAPATAZ | F32: hh | G32: 0.1 | H32: =ROUND(G32*8/$D$29,4) -> 0.0267 | I32: 34.73 | J32: =ROUND(H32*I32,2) -> 0.93 | K32: 47
B33: PEON | F33: hh | G33: 1 | H33: =ROUND(G33*8/$D$29,4) -> 0.2667 | I33: 20.51 | J33: =ROUND(H33*I33,2) -> 5.47 | K33: 47
B34: OPERADOR EQUIPO LIVIANO | F34: hh | G34: 1 | H34: =ROUND(G34*8/$D$29,4) -> 0.2667 | I34: 29.94 | J34: =ROUND(H34*I34,2) -> 7.98 | K34: 47
J35: =ROUND(SUM(J32:J34),2) -> 14.38
B36: Materiales
B37: MATERIAL GRANULAR | F37: m3 | H37: 1.05 | I37: 44.07 | J37: =ROUND(H37*I37,2) -> 46.27 | K37: 5
B38: AGUA | F38: m3 | H38: 0.08 | I38: 6.14 | J38: =ROUND(H38*I38,2) -> 0.49 | K38: 30
J39: =ROUND(SUM(J37:J38),2) -> 46.76
B40: Equipos
B41: HERRAMIENTAS MANUALES | F41: %mo | H41: 3 | I41: =J35 -> 14.38 | J41: =ROUND(H41%*I41,2) -> 0.43 | K41: 37
B42: APISONADOR TIPO CANGURO | F42: hm | G42: 1 | H42: =ROUND(G42*8/$D$29,4) -> 0.2667 | I42: 17.47 | J42: =ROUND(H42*I42,2) -> 4.66 | K42: 49
J43: =ROUND(SUM(J41:J42),2) -> 5.09
A45: Partida | B45: =ESTRUCTURA!A8 -> 02.01.04 | C45: RELLENO COMPACTADO C/PLANCHA COMPACTADORA C/MATERIAL PROPIO
A46: Rendimiento m2/día | B46: m3/dia | C46: M.O | D46: 40 | E46: EQ | F46: =D46 -> 40 | G46: Costo unitario directo | I46: m3 | J46: =J52+J55+J60 -> 19.77
...

Sheet ARQUITECTURA
G2: Unidad | H2: Metrado | I2: C.U | J2: Parcial | K2: Total
A3: 3 | B3: ARQUITECTURA | K3: =J4+J10+J19+J26+J33+J39+J43 -> 1039120.6
A4: 3.01 | B4: MUROS DE MAMPOSTERIA | J4: =SUM(J5:J9) -> 282960.31
A5: 03.01.01 | B5: MURO DE LADRILLO KK TIPO IV SOGA M 1:4 E=1.5 CM | G5: m2 | H5: =ROUND(SUM(BIBLIOTECA:INGRESO!G6),2) -> 1048.34 | I5: =ROUND('APUS ARQUITECTURA'!J5,2) -> 140.28 | J5: =ROUND(H5*I5,2) -> 147061.14
A6: 03.01.02 | B6: MURO DE LADRILLO KK TIPO IV CABEZA M 1:4 E=1.5 CM | G6: m2 | H6: =ROUND(SUM(BIBLIOTECA:INGRESO!G7),2) -> 345.85 | I6: =ROUND('APUS ARQUITECTURA'!J32,2) -> 166.43 | J6: =ROUND(H6*I6,2) -> 57559.82
A7: 03.01.03 | B7: TABIQUE DE DRYWALL E=0.15m | G7: m2 | H7: =ROUND(SUM(BIBLIOTECA:INGRESO!G8),2) -> 287.32 | I7: =ROUND('APUS ARQUITECTURA'!J50,2) -> 141.08 | J7: =ROUND(H7*I7,2) -> 40535.11
A8: 03.01.04 | B8: MELAMINE | G8: m2 | H8: =ROUND(SUM(BIBLIOTECA:INGRESO!G9),2) -> 156.6 | I8: =ROUND('APUS ARQUITECTURA'!J74,2) -> 204.42 | J8: =ROUND(H8*I8,2) -> 32012.17
A9: 03.01.05 | B9: TABLERO C.A. C/CERAMICO | G9: m2 | H9: =ROUND(SUM(BIBLIOTECA:INGRESO!G10),2) -> 12.3 | I9: =ROUND('APUS ARQUITECTURA'!J92,2) -> 470.9 | J9: =ROUND(H9*I9,2) -> 5792.07
A10: 3.02 | B10: REVOQUES, ENLUCIDOS y MOLDURAS | J10: =J11+J14+J16 -> 224988.3
A11: 03.02.01 | B11: TARRAJEO | J11: =SUM(J12:J13) -> 65308.96
A12: 03.02.01.01 | B12: TARRAJEO FROTACHADO EN MUROS INTERIORES | G12: m2 | H12: =ROUND(SUM(BIBLIOTECA:INGRESO!G13),2) -> 1392.44 | I12: =ROUND('APUS ARQUITECTURA'!J127,2) -> 27.34 | J12: =ROUND(H12*I12,2) -> 38069.31
A13: 03.02.01.02 | B13: TARRAJEO FROTACHADO EN MUROS EXTERIORES | G13: m2 | H13: =ROUND(SUM(BIBLIOTECA:INGRESO!G14),2) -> 754.77 | I13: =ROUND('APUS ARQUITECTURA'!J148,2) -> 36.09 | J13: =ROUND(H13*I13,2) -> 27239.65
A14: 03.02.02 | B14: ZOCALO | J14: =SUM(J15) -> 72069.06
A15: 03.02.02.01 | B15: ZOCALO DE CERAMICA 0.30x0.30 | G15: m2 | H15: =ROUND(SUM(BIBLIOTECA:INGRESO!G16),2) -> 793.45 | I15: =ROUND('APUS ARQUITECTURA'!J168,2) -> 90.83 | J15: =ROUND(H15*I15,2) -> 72069.06
A16: 03.02.03 | B16: CIELO RASO | J16: =SUM(J17:J18) -> 87610.28
A17: 03.02.03.01 | B17: FALSO CIELORRADOS DE BALDOSAS DE FIBRA MINERAL DE 0.61x0.61m, e:15mm, BORDE REBAJADO, CON SISTEMA DE SUSPENSION ANTISISMICO | G17: m3 | H17: =ROUND(SUM(BIBLIOTECA:INGRESO!G18),2) -> 160 | I17: =ROUND('APUS ARQUITECTURA'!J188,2) -> 213.18 | J17: =ROUND(H17*I17,2) -> 34108.8
A18: 03.02.03.02 | B18: TARRAJEO DE CIELO RASO MEZCLA C:A 1:5, e=0.15cm | G18: m3 | H18: =ROUND(SUM(BIBLIOTECA:INGRESO!G19),2) -> 866 | I18: =ROUND('APUS ARQUITECTURA'!J212,2) -> 61.78 | J18: =ROUND(H18*I18,2) -> 53501.48
A19: 3.03 | B19: PISOS Y PAVIMENTOS | J19: =SUM(J20:J25) -> 193026.6
A20: 03.03.01 | B20: CONTRAPISOS E=40MM C:A 1:4 | G20: m2 | H20: =ROUND(SUM(BIBLIOTECA:INGRESO!G21),2) -> 1000 | I20: =ROUND('APUS ARQUITECTURA'!J232,2) -> 49.73 | J20: =ROUND(H20*I20,2) -> 49730
A21: 03.03.02 | B21: PISO PORCELANATO ANTIDESLIZANTE 0.60x0.6OM | G21: m2 | H21: =ROUND(SUM(BIBLIOTECA:INGRESO!G22),2) -> 320 | I21: =ROUND('APUS ARQUITECTURA'!J252,2) -> 206.78 | J21: =ROUND(H21*I21,2) -> 66169.6
A22: 03.03.03 | B22: PISO DE BALDOSA CERAMICA 30x30 | G22: m2 | H22: =ROUND(SUM(BIBLIOTECA:INGRESO!G23),2) -> 380 | I22: =ROUND('APUS ARQUITECTURA'!J272,2) -> 102.66 | J22: =ROUND(H22*I22,2) -> 39010.8
A23: 03.03.04 | B23: PISO DE CONCRETO E=4" - FC=175 KG7CM2 / ACABADO FROTACHADO | G23: m2 | H23: =ROUND(SUM(BIBLIOTECA:INGRESO!G24),2) -> 100 | I23: =ROUND('APUS ARQUITECTURA'!J292,2) -> 47.45 | J23: =ROUND(H23*I23,2) -> 4745
A24: 03.03.05 | B24: PISO DE CEMENTO PULIDO Y BRUÑADO E=2" S/ COLOREAR | G24: m2 | H24: =ROUND(SUM(BIBLIOTECA:INGRESO!G25),2) -> 100 | I24: =ROUND('APUS ARQUITECTURA'!J318,2) -> 51.99 | J24: =ROUND(H24*I24,2) -> 5199
A25: 03.03.06 | B25: PISO LAMINADO DE ALTO TRANSITO EN AULAS | G25: m2 | H25: =ROUND(SUM(BIBLIOTECA:INGRESO!G26),2) -> 140 | I25: =ROUND('APUS ARQUITECTURA'!J340,2) -> 201.23 | J25: =ROUND(H25*I25,2) -> 28172.2
A26: 3.04 | B26: CONTRAZOCALOS | J26: =SUM(J27:J32) -> 33501.05
A27: 03.04.01 | B27: CONTR. S/COLOREAR H=30cm MZ 1:2 e=1.5cm | G27: m | H27: =ROUND(SUM(BIBLIOTECA:INGRESO!G28),2) -> 82.3 | I27: =ROUND('APUS ARQUITECTURA'!J347,2) -> 20.58 | J27: =ROUND(H27*I27,2) -> 1693.73
A28: 03.04.02 | B28: CONTRAZOCALO DE CEMENTO SEMIPULIDO CON IMPERMEABILIZANTE Y ENDURECEDOR | G28: m | H28: =ROUND(SUM(BIBLIOTECA:INGRESO!G29),2) -> 393.14 | I28: =ROUND('APUS ARQUITECTURA'!J364,2) -> 26.7 | J28: =ROUND(H28*I28,2) -> 10496.84
A29: 03.04.03 | B29: CONTRAZOCALO PORCELANATO ANTIDESLIZANTE H=0.10M | G29: m | H29: =ROUND(SUM(BIBLIOTECA:INGRESO!G30),2) -> 177.6 | I29: =ROUND('APUS ARQUITECTURA'!J383,2) -> 36.55 | J29: =ROUND(H29*I29,2) -> 6491.28
A30: 03.04.04 | B30: CONTRAZOCALO LAMINADO EN AULAS | G30: m | H30: =ROUND(SUM(BIBLIOTECA:INGRESO!G31),2) -> 63.91 | I30: =ROUND('APUS ARQUITECTURA'!J403,2) -> 25 | J30: =ROUND(H30*I30,2) -> 1597.75
A31: 03.04.05 | B31: CONTRAZOCALO DE BALDOSA CERAMICA H=30cm | G31: m | H31: =ROUND(SUM(BIBLIOTECA:INGRESO!G32),2) -> 117.83 | I31: =ROUND('APUS ARQUITECTURA'!J410,2) -> 44.2 | J31: =ROUND(H31*I31,2) -> 5208.09
A32: 03.04.06 | B32: CONTRAZOCALO SANITARIO TERRAZO PULIDO, H=0,10M | G32: m | H32: =ROUND(SUM(BIBLIOTECA:INGRESO!G33),2) -> 94.9 | I32: =ROUND('APUS ARQUITECTURA'!J430,2) -> 84.44 | J32: =ROUND(H32*I32,2) -> 8013.36
A33: 3.05 | B33: CARPINTERIA | J33: =SUM(J34:J38) -> 233643.5
A34: 03.05.01 | B34: PUERTA DE MADERA ROBLE NACIONAL APANELADA TIPO MACHIMBRADA +SOBRELUZ+VIDRIO TEMPLADO DE 8MM DE 02 HOJAS+INST+ACABADO, SEGUN PLANO Y ET | G34: m2 | H34: =ROUND(SUM(BIBLIOTECA:INGRESO!G35),2) -> 135.16 | I34: =ROUND('APUS ARQUITECTURA'!J449,2) -> 560.62 | J34: =ROUND(H34*I34,2) -> 75773.4
A35: 03.05.02 | B35: VENTANA C/MARCO DE ALUMINIO SISTEMA CORREDIZO TIPO SERIE 3160 + VIDRIOS INCOLORO TEMPLADO DE 8MM+ACCESORIO + ACCESORIO+ INSTALACION, SEGUN PLANO Y ESPECIFICACIONES TECNICAS | G35: m2 | H35: =ROUND(SUM(BIBLIOTECA:INGRESO!G36),2) -> 124.47 | I35: =ROUND('APUS ARQUITECTURA'!J456,2) -> 367.87 | J35: =ROUND(H35*I35,2) -> 45788.78
A36: 03.05.03 | B36: MAMPARA DE ALUMINIO+VIDRIO INCOLORO TEMPLADO 8MM+ACCESORIOS+INSTALACION,SEGUN PLANO Y ESPECIFICACIONES TECNICAS | G36: m2 | H36: =ROUND(SUM(BIBLIOTECA:INGRESO!G37),2) -> 66.35 | I36: =ROUND('APUS ARQUITECTURA'!J463,2) -> 514.54 | J36: =ROUND(H36*I36,2) -> 34139.73
A37: 03.05.04 | B37: PARASOLES | G37: m | H37: =ROUND(SUM(BIBLIOTECA:INGRESO!G38),2) -> 122.2 | I37: =ROUND('APUS ARQUITECTURA'!J470,2) -> 622.13 | J37: =ROUND(H37*I37,2) -> 76024.29
A38: 03.05.05 | B38: PERSIANA METALICA | G38: m2 | H38: =ROUND(SUM(BIBLIOTECA:INGRESO!G39),2) -> 35 | I38: =ROUND('APUS ARQUITECTURA'!J477,2) -> 54.78 | J38: =ROUND(H38*I38,2) -> 1917.3
A39: 3.06 | B39: PINTURA | J39: =SUM(J40:J41) -> 48739.24
A40: 03.06.01 | B40: PINTURA LATEX PARA INTERIOR - 2 MANOS (MUROS, TECHOS, VIGAS Y COLUMNAS) | G40: m2 | H40: =ROUND(SUM(BIBLIOTECA:INGRESO!G41),2) -> 2395.93 | I40: =ROUND('APUS ARQUITECTURA'!J484,2) -> 15.63 | J40: =ROUND(H40*I40,2) -> 37448.39
A41: 03.06.02 | B41: PINTURA OLEO PARA EXTERIORES - 2 MANOS | G41: m2 | H41: =ROUND(SUM(BIBLIOTECA:INGRESO!G42),2) -> 707.89 | I41: =ROUND('APUS ARQUITECTURA'!J504,2) -> 15.95 | J41: =ROUND(H41*I41,2) -> 11290.85
...

Sheet APUS ARQUITECTURA
A4: Partida | B4: =ARQUITECTURA!A5 -> 03.01.01 | C4: MURO DE LADRILLO KK TIPO IV SOGA M 1:4 E=1.5 CM | R4: Partida | S4: =A22 -> 100000000010 | T4: COLUMNETAS - CONCRETO f'c=210 kg/cm²
A5: Rendimiento m2/día | B5: m2/dia | C5: M.O | D5: 16 | E5: EQ | F5: =D5 -> 16 | G5: Costo unitario directo | I5: m2 | J5: =J10+J16+J20+J29 -> 140.28 | R5: Rendimiento m2/día | S5: m3/dia | T5: M.O | U5: 10 | V5: EQ | W5: =U5 -> 10 | X5: Costo unitario directo | Z5: m3 | AA5: =AA11+AA18+AA23 -> 493.41
A6: Código | B6: Descripción Recurso | F6: Unidad | G6: Cuadrilla | H6: Cantidad | I6: Precio (S/.) | J6: Parcial (S/.) | R6: Código | S6: Descripción Recurso | W6: Unidad | X6: Cuadrilla | Y6: Cantidad | Z6: Precio (S/.) | AA6: Parcial (S/.)
B7: Mano de Obra | S7: Mano de Obra
B8: OPERARIO | F8: hh | G8: 2 | H8: =ROUND(G8*8/$D$5,4) -> 1 | I8: 28.94 | J8: =ROUND(H8*I8,2) -> 28.94 | K8: 47 | S8: OPERARIO | W8: hh | X8: 2 | Y8: =ROUND(X8*8/$U$5,4) -> 1.6 | Z8: 28.94 | AA8: =ROUND(Y8*Z8,2) -> 46.3 | AB8: 47
B9: PEON | F9: hh | G9: 1 | H9: =ROUND(G9*8/$D$5,4) -> 0.5 | I9: 20.51 | J9: =ROUND(H9*I9,2) -> 10.26 | K9: 47 | S9: OFICIAL | W9: hh | X9: 1 | Y9: =ROUND(X9*8/$U$5,4) -> 0.8 | Z9: 22.66 | AA9: =ROUND(Y9*Z9,2) -> 18.13 | AB9: 47
J10: =ROUND(SUM(J8:J9),2) -> 39.2 | S10: PEON | W10: hh | X10: 8 | Y10: =ROUND(X10*8/$U$5,4) -> 6.4 | Z10: 20.51 | AA10: =ROUND(Y10*Z10,2) -> 131.26 | AB10: 47
B11: Materiales | AA11: =ROUND(SUM(AA8:AA10),2) -> 195.69
B12: AGUA | F12: m3 | H12: 0.0068 | I12: 6.14 | J12: =ROUND(H12*I12,2) -> 0.04 | K12: 30 | S12: Materiales
B13: ARENA GRUESA | F13: m3 | H13: 0.0269 | I13: 47 | J13: =ROUND(H13*I13,2) -> 1.26 | K13: 4 | S13: PIEDRA CHANCADA DE 1/2" Y 3/4" | W13: m3 | Y13: 0.55 | Z13: 55.08 | AA13: =ROUND(Y13*Z13,2) -> 30.29 | AB13: 5
B14: CEMENTO PORTLAND TIPO I (42.5 kg) | F14: bls | H14: 0.2211 | I14: 24.52 | J14: =ROUND(H14*I14,2) -> 5.42 | K14: 21 | S14: ARENA GRUESA | W14: m3 | Y14: 0.54 | Z14: 47 | AA14: =ROUND(Y14*Z14,2) -> 25.38 | AB14: 4
B15: LADRILLO KK TIPO IV 24X13X9 CM | F15: und | H15: 39 | I15: 1.02 | J15: =ROUND(H15*I15,2) -> 39.78 | K15: 17 | S15: CEMENTO PORTLAND TIPO I (42.5 kg) | W15: bls | Y15: 8.43 | Z15: 24.52 | AA15: =ROUND(Y15*Z15,2) -> 206.7 | AB15: 21
J16: =ROUND(SUM(J12:J15),2) -> 46.5 | S16: AGUA | W16: m3 | Y16: 0.185 | Z16: 6.14 | AA16: =ROUND(Y16*Z16,2) -> 1.14 | AB16: 30
B17: Equipos | S17: GASOLINA DE 84 OCTANOS | W17: gal | Y17: 0.36 | Z17: 13.93 | AA17: =ROUND(Y17*Z17,2) -> 5.01 | AB17: 34
B18: HERRAMIENTAS MANUALES | F18: %mo | H18: 3 | I18: =J10 -> 39.2 | J18: =ROUND(H18%*I18,2) -> 1.18 | K18: 37 | AA18: =ROUND(SUM(AA13:AA17),2) -> 268.52
B19: ANDAMIO METALICO HOMOLOGADO | F19: d | G19: 2 | H19: =ROUND(G19*8/$D$5,4) -> 1 | I19: 10.34 | J19: =ROUND(H19*I19,2) -> 10.34 | K19: 39 | S19: Equipos
J20: =ROUND(SUM(J18:J19),2) -> 11.52 | S20: HERRAMIENTAS MANUALES | W20: %mo | Y20: 3 | Z20: =AA11 -> 195.69 | AA20: =ROUND(Y20%*Z20,2) -> 5.87 | AB20: 37
B21: Subpartidas | S21: MEZCLADORA DE CONCRETO TAMBOR 11 p3 18 HP | W21: hm | X21: 1 | Y21: =ROUND(X21*8/$U$5,4) -> 0.8 | Z21: 25.63 | AA21: =ROUND(Y21*Z21,2) -> 20.5 | AB21: 48
A22: 100000000010 | B22: COLUMNETAS - CONCRETO F'C= 210 kg/cm2 | F22: m3 | H22: 0.011 | I22: =AA5 -> 493.41 | J22: =ROUND(H22*I22,2) -> 5.43 | S22: VIBRADOR A GASOLINA Y 1 3/4" , 4 HP | W22: hm | X22: 0.5 | Y22: =ROUND(X22*8/$U$5,4) -> 0.4 | Z22: 7.07 | AA22: =ROUND(Y22*Z22,2) -> 2.83 | AB22: 49
A23: 100000000011 | B23: COLUMNETAS - ENCOFRADO Y DESENCOFRADO | F23: m2 | H23: 0.1069 | I23: =AA26 -> 56.16 | J23: =ROUND(H23*I23,2) -> 6 | AA23: =ROUND(SUM(AA20:AA22),2) -> 29.2
A24: 100000000012 | B24: COLUMNETAS - ACERO DE REFUERZO Fy= 4200 kg/cm2 | F24: kg | H24: 0.9331 | I24: =AA42 -> 5.54 | J24: =ROUND(H24*I24,2) -> 5.17
A25: 100000000013 | B25: VIGUETAS - CONCRETO F'C= 210 kg/cm2 | F25: m3 | H25: 0.0058 | I25: =AA58 -> 377.33 | J25: =ROUND(H25*I25,2) -> 2.19 | R25: Partida | S25: =A23 -> 100000000011 | T25: COLUMNETAS - ENCOFRADO Y DESENCOFRADO NORMAL
A26: 100000000014 | B26: VIGUETAS - ENCOFRADO Y DESENCOFRADO | F26: m2 | H26: 0.0774 | I26: =AA79 -> 71.15 | J26: =ROUND(H26*I26,2) -> 5.51 | R26: Rendimiento m2/día | S26: m2/dia | T26: M.O | U26: 12 | V26: EQ | W26: =U26 -> 12 | X26: Costo unitario directo | Z26: m2 | AA26: =AA31+AA36+AA39 -> 56.16
A27: 100000000015 | B27: VIGUETAS - ACERO DE REFUERZO Fy= 4200 kg/cm2 | F27: kg | H27: 0.9009 | I27: =AA96 -> 5.54 | J27: =ROUND(H27*I27,2) -> 4.99 | R27: Código | S27: Descripción Recurso | W27: Unidad | X27: Cuadrilla | Y27: Cantidad | Z27: Precio (S/.) | AA27: Parcial (S/.)
A28: 100000000016 | B28: JUNTAS CON ESPUMA PLASTICO + SELLO ELASTOMERICO DE POLIURETANO E=0.15M | F28: m | H28: 0.2487 | I28: =AA112 -> 55.35 | J28: =ROUND(H28*I28,2) -> 13.77 | S28: Mano de Obra
J29: =ROUND(SUM(J22:J28),2) -> 43.06 | S29: OPERARIO | W29: hh | X29: 1 | Y29: =ROUND(X29*8/$U$26,4) -> 0.6667 | Z29: 28.94 | AA29: =ROUND(Y29*Z29,2) -> 19.29 | AB29: 47
S30: PEON | W30: hh | X30: 1 | Y30: =ROUND(X30*8/$U$26,4) -> 0.6667 | Z30: 20.51 | AA30: =ROUND(Y30*Z30,2) -> 13.67 | AB30: 47
A31: Partida | B31: =ARQUITECTURA!A6 -> 03.01.02 | C31: MURO DE LADRILLO KK TIPO IV CABEZA M 1:4 E=1.5 CM | AA31: =ROUND(SUM(AA29:AA30),2) -> 32.96
A32: Rendimiento m2/día | B32: m2/dia | C32: M.O | D32: 10 | E32: EQ | F32: =D32 -> 10 | G32: Costo unitario directo | I32: m2 | J32: =J37+J43+J47 -> 166.43 | S32: Materiales
A33: Código | B33: Descripción Recurso | F33: Unidad | G33: Cuadrilla | H33: Cantidad | I33: Precio (S/.) | J33: Parcial (S/.) | S33: ALAMBRE NEGRO RECOCIDO BWG N 8 | W33: kg | Y33: 0.2 | Z33: 2.64 | AA33: =ROUND(Y33*Z33,2) -> 0.53 | AB33: 2
B34: Mano de Obra | S34: CLAVO C/CABEZA P/CONSTRUCCION D.PROMEDIO | W34: kg | Y34: 0.25 | Z34: 5.51 | AA34: =ROUND(Y34*Z34,2) -> 1.38 | AB34: 2
B35: OPERARIO | F35: hh | G35: 2 | H35: =ROUND(G35*8/$D$32,4) -> 1.6 | I35: 28.94 | J35: =ROUND(H35*I35,2) -> 46.3 | K35: 47 | S35: MADERA TORNILLO | W35: p2 | Y35: 3.5 | Z35: 5.8 | AA35: =ROUND(Y35*Z35,2) -> 20.3 | AB35: 43
B36: PEON | F36: hh | G36: 1 | H36: =ROUND(G36*8/$D$32,4) -> 0.8 | I36: 20.51 | J36: =ROUND(H36*I36,2) -> 16.41 | K36: 47 | AA36: =ROUND(SUM(AA33:AA35),2) -> 22.21
J37: =ROUND(SUM(J35:J36),2) -> 62.71 | S37: Equipos
B38: Materiales | S38: HERRAMIENTAS MANUALES | W38: %mo | Y38: 3 | Z38: =AA31 -> 32.96 | AA38: =ROUND(Y38%*Z38,2) -> 0.99 | AB38: 37
B39: AGUA | F39: m3 | H39: 0.015 | I39: 6.14 | J39: =ROUND(H39*I39,2) -> 0.09 | K39: 30 | AA39: =ROUND(SUM(AA38),2) -> 0.99
B40: ARENA GRUESA | F40: m3 | H40: 0.06 | I40: 47 | J40: =ROUND(H40*I40,2) -> 2.82 | K40: 4
B41: CEMENTO PORTLAND TIPO I (42.5 kg) | F41: bls | H41: 0.49 | I41: 24.52 | J41: =ROUND(H41*I41,2) -> 12.01 | K41: 21 | R41: Partida | S41: =A24 -> 100000000012 | T41: COLUMNETAS - ACERO fy=4200 kg/cm²
B42: LADRILLO KK TIPO IV 24X13X9 CM | F42: und | H42: 69 | I42: 1.02 | J42: =ROUND(H42*I42,2) -> 70.38 | K42: 17 | R42: Rendimiento m2/día | S42: m2/dia | T42: M.O | U42: 250 | V42: EQ | W42: =U42 -> 250 | X42: Costo unitario directo | Z42: m2 | AA42: =AA47+AA51+AA55 -> 5.54
J43: =ROUND(SUM(J39:J42),2) -> 85.3 | R43: Código | S43: Descripción Recurso | W43: Unidad | X43: Cuadrilla | Y43: Cantidad | Z43: Precio (S/.) | AA43: Parcial (S/.)
...

Sheet SANITARIAS
G2: Unidad | H2: Metrado | I2: C.U | J2: Parcial | K2: Total
A3: 4 | B3: INSTALACIONES SANITARIAS | K3: =J4+J9+J12+J14+J16+J18+J21+J23+J26 -> 647777.59
A4: 4.01 | B4: APARATOS SANITARIOS | J4: =SUM(J5:J8) -> 77385.49
A5: 04.01.01 | B5: INODORO | G5: und | H5: =ROUNDUP(SUM(BIBLIOTECA:INGRESO!G44),0) -> 159 | I5: =ROUND('APUS SANITARIAS'!J5,2) -> 193.31 | J5: =ROUND(H5*I5,2) -> 30736.29
A6: 04.01.02 | B6: URINARIO | G6: und | H6: =ROUNDUP(SUM(BIBLIOTECA:INGRESO!G45),0) -> 91 | I6: =ROUND('APUS SANITARIAS'!J12,2) -> 192.4 | J6: =ROUND(H6*I6,2) -> 17508.4
A7: 04.01.03 | B7: LAVATORIO | G7: und | H7: =ROUNDUP(SUM(BIBLIOTECA:INGRESO!G46),0) -> 165 | I7: =ROUND('APUS SANITARIAS'!J19,2) -> 67.52 | J7: =ROUND(H7*I7,2) -> 11140.8
A8: 04.01.04 | B8: LAVADEROS DE LIMPIEZA DE MAMPOSTERIA DE LADRILLO REVESTIDO CON CERAMICA + GRIFERIA | G8: und | H8: =ROUNDUP(SUM(BIBLIOTECA:INGRESO!G47),0) -> 24 | I8: =ROUND('APUS SANITARIAS'!J26,2) -> 750 | J8: =ROUND(H8*I8,2) -> 18000
A9: 4.02 | B9: SALIDAS DE AGUA | J9: =SUM(J10:J11) -> 37638.69
A10: 04.02.01 | B10: SALIDA DE AGUA FRIA PVC INC. TUBERIA Y ACCESORIOS 1/2" | G10: pto | H10: =ROUNDUP(SUM(BIBLIOTECA:INGRESO!G48),0) -> 193 | I10: =ROUND('APUS SANITARIAS'!J32,2) -> 131.73 | J10: =ROUND(H10*I10,2) -> 25423.89
A11: 04.02.02 | B11: SALIDA DE AGUA CALIENTE, CON TUBERIA CPVC (PROMEDIO) | G11: pto | H11: =ROUNDUP(SUM(BIBLIOTECA:INGRESO!G49),0) -> 58 | I11: =ROUND('APUS SANITARIAS'!J50,2) -> 210.6 | J11: =ROUND(H11*I11,2) -> 12214.8
A12: 4.03 | B12: VALVULAS | J12: =SUM(J13) -> 38400
A13: 04.03.01 | B13: VALVULAS COMPUERTAS, ESFERICAS Y CAJAS PARA VALVULAS | G13: und | H13: =ROUNDUP(SUM(BIBLIOTECA:INGRESO!G50),0) -> 192 | I13: =ROUND('APUS SANITARIAS'!J69,2) -> 200 | J13: =ROUND(H13*I13,2) -> 38400
A14: 4.04 | B14: EXTINTORES Y GABINETES | J14: =SUM(J15) -> 8595.52
A15: 04.04.01 | B15: EXTINTORES Y GABINETES | G15: und | H15: =ROUNDUP(SUM(BIBLIOTECA:INGRESO!G51),0) -> 16 | I15: =ROUND('APUS SANITARIAS'!J76,2) -> 537.22 | J15: =ROUND(H15*I15,2) -> 8595.52
A16: 4.05 | B16: SALIDAS DRENAJE PLUVIAL | J16: =SUM(J17) -> 790.75
A17: 04.05.01 | B17: DRENAJE PLUVIAL | G17: pto | H17: =ROUND(1.3*'Datos iniciales '!B3/75,0) -> 5 | I17: =ROUND('APUS SANITARIAS'!J91,2) -> 158.15 | J17: =ROUND(H17*I17,2) -> 790.75
A18: 4.06 | B18: DESAGÜE | J18: =SUM(J19:J20) -> 57487.18
A19: 04.06.01 | B19: SALIDA DE DESAGUE PVC-SAL 2" | G19: pto | H19: =ROUNDUP(SUM(BIBLIOTECA:INGRESO!G53),0) -> 202 | I19: =ROUND('APUS SANITARIAS'!J108,2) -> 138.65 | J19: =ROUND(H19*I19,2) -> 28007.3
A20: 04.06.02 | B20: SALIDA DE DESAGUE PVC-SAL 4" | G20: pto | H20: =ROUNDUP(SUM(BIBLIOTECA:INGRESO!G54),0) -> 202 | I20: =ROUND('APUS SANITARIAS'!J127,2) -> 145.94 | J20: =ROUND(H20*I20,2) -> 29479.88
A21: 4.07 | B21: VENTILACIÓN | J21: =SUM(J22) -> 28498.16
A22: 04.07.01 | B22: SALIDA DE VENTILACION (PROMEDIO) | G22: pto | H22: =ROUNDUP(SUM(BIBLIOTECA:INGRESO!G55),0) -> 202 | I22: =ROUND('APUS SANITARIAS'!J145,2) -> 141.08 | J22: =ROUND(H22*I22,2) -> 28498.16
A23: 4.08 | B23: ACCESORIOS | J23: =SUM(J24:J25) -> 17491.65
A24: 04.08.01 | B24: MEZCLADORA DE DUCHA | G24: und | H24: =ROUNDUP(SUM(BIBLIOTECA:INGRESO!G56),0) -> 55 | I24: =ROUND('APUS SANITARIAS'!J163,2) -> 214.34 | J24: =ROUND(H24*I24,2) -> 11788.7
A25: 04.08.02 | B25: JABONERA DE LOSA PARA EMPOTRAR | G25: und | H25: =ROUNDUP(SUM(BIBLIOTECA:INGRESO!G57),0) -> 55 | I25: =ROUND('APUS SANITARIAS'!J178,2) -> 103.69 | J25: =ROUND(H25*I25,2) -> 5702.95
A26: 4.09 | B26: INSTALACIONES EXTERIORES | J26: =SUM(J27:J29) -> 381490.15
A27: 04.09.01 | B27: SISTEMA DE BOMBEO DE PRESIÓN CONSTANTE | G27: Glb | H27: 1 | I27: =ROUND('APUS SANITARIAS'!J195,2) -> 79716.91 | J27: =ROUND(H27*I27,2) -> 79716.91
A28: 04.09.02 | B28: INSTALACIONES SANITARIAS EXTERIORES INC. CANALETAS DE EVACUACIÓN PLUVIAL | G28: Glb | H28: 1 | I28: =ROUND('APUS SANITARIAS'!J202,2) -> 131735.24 | J28: =ROUND(H28*I28,2) -> 131735.24
A29: 04.09.03 | B29: SISTEMA DE AGUA CONTRA INCENDIOS (RED CONTRA INCENDIOS, GABINETES) | G29: Glb | H29: 1 | I29: =ROUND('APUS SANITARIAS'!J209,2) -> 170038 | J29: =ROUND(H29*I29,2) -> 170038

Sheet APUS SANITARIAS
A4: Partida | B4: =SANITARIAS!A5 -> 04.01.01 | C4: INODORO
A5: Rendimiento m2/día | B5: und/dia | C5: M.O | D5: 35 | E5: EQ | F5: =D5 -> 35 | G5: Costo unitario directo | I5: und | J5: =J9 -> 193.31
A6: Código | B6: Descripción Recurso | F6: Unidad | G6: Cuadrilla | H6: Cantidad | I6: Precio (S/.) | J6: Parcial (S/.)
B7: Materiales
B8: INODORO | F8: und | H8: 0.3333 | I8: 580 | J8: =ROUND(H8*I8,2) -> 193.31 | K8: 10
J9: =ROUND(SUM(J8),2) -> 193.31
A11: Partida | B11: =SANITARIAS!A6 -> 04.01.02 | C11: URINARIO
A12: Rendimiento m2/día | B12: und/dia | C12: M.O | D12: 35 | E12: EQ | F12: =D12 -> 35 | G12: Costo unitario directo | I12: und | J12: =J16 -> 192.4
A13: Código | B13: Descripción Recurso | F13: Unidad | G13: Cuadrilla | H13: Cantidad | I13: Precio (S/.) | J13: Parcial (S/.)
B14: Materiales
B15: URINARIO | F15: und | H15: 0.3333 | I15: 577.26 | J15: =ROUND(H15*I15,2) -> 192.4 | K15: 10
J16: =ROUND(SUM(J15),2) -> 192.4
A18: Partida | B18: =SANITARIAS!A7 -> 04.01.03 | C18: LAVATORIO
A19: Rendimiento m2/día | B19: und/dia | C19: M.O | D19: 35 | E19: EQ | F19: =D19 -> 35 | G19: Costo unitario directo | I19: und | J19: =J23 -> 67.52
A20: Código | B20: Descripción Recurso | F20: Unidad | G20: Cuadrilla | H20: Cantidad | I20: Precio (S/.) | J20: Parcial (S/.)
B21: Materiales
B22: LAVATORIO | F22: und | H22: 0.3333 | I22: 202.57 | J22: =ROUND(H22*I22,2) -> 67.52 | K22: 10
J23: =ROUND(SUM(J22:J22),2) -> 67.52
A25: Partida | B25: =SANITARIAS!A8 -> 04.01.04 | C25: LAVADEROS DE LIMPIEZA DE MAMPOSTERIA DE LADRILLO REVESTIDO CON CERAMICA + GRIFERIA
A26: Rendimiento m2/día | B26: und/dia | C26: M.O | D26: 1 | E26: EQ | F26: =D26 -> 1 | G26: Costo unitario directo | I26: und | J26: =J30 -> 750
A27: Código | B27: Descripción Recurso | F27: Unidad | G27: Cuadrilla | H27: Cantidad | I27: Precio (S/.) | J27: Parcial (S/.)
B28: Materiales
B29: LAVADEROS DE LIMPIEZA DE MAMPOSTERIA DE LADRILLO REVESTIDO CON CERAMICA + GRIFERIA | F29: und | H29: 1 | I29: 750 | J29: =ROUND(H29*I29,2) -> 750 | K29: 10
J30: =ROUND(SUM(J29),2) -> 750
A31: Partida | B31: =SANITARIAS!A10 -> 04.02.01 | C31: SALIDA DE AGUA FRIA PVC INC. TUBERIA Y ACCESORIOS 1/2"
A32: Rendimiento m2/día | B32: pto/dia | C32: M.O | D32: 3 | E32: EQ | F32: =D32 -> 3 | G32: Costo unitario directo | I32: pto | J32: =J38+J44+J47 -> 131.73
A33: Código | B33: Descripción Recurso | F33: Unidad | G33: Cuadrilla | H33: Cantidad | I33: Precio (S/.) | J33: Parcial (S/.)
B34: Mano de Obra
B35: CAPATAZ | F35: hh | G35: 0.1 | H35: =ROUND(G35*8/$D$32,4) -> 0.2667 | I35: 34.73 | J35: =ROUND(H35*I35,2) -> 9.26 | K35: 47
B36: OPERARIO | F36: hh | G36: 1 | H36: =ROUND(G36*8/$D$32,4) -> 2.6667 | I36: 28.94 | J36: =ROUND(H36*I36,2) -> 77.17 | K36: 47
B37: PEON | F37: hh | G37: 0.5 | H37: =ROUND(G37*8/$D$32,4) -> 1.3333 | I37: 20.51 | J37: =ROUND(H37*I37,2) -> 27.35 | K37: 47
J38: =ROUND(SUM(J35:J37),2) -> 113.78
B39: Materiales
B40: PEGAMENTO PVC AZUL 128 ONZAS - OATEY | F40: gal | H40: 0.03 | I40: 189.66 | J40: =ROUND(H40*I40,2) -> 5.69 | K40: 30
B41: TUBO PVC AGUA S.P. CLASE 10 1/2" X 5m | F41: pza | H41: 0.412 | I41: 11.27 | J41: =ROUND(H41*I41,2) -> 4.64 | K41: 72
B42: CODO PVC AGUA DOBLE CAMPANA S.P. 1/2" X 90° | F42: pza | H42: 2 | I42: 1.19 | J42: =ROUND(H42*I42,2) -> 2.38 | K42: 72
B43: TEE PVC AGUA S.P. 1/2" | F43: pza | H43: 1 | I43: 1.83 | J43: =ROUND(H43*I43,2) -> 1.83 | K43: 72
J44: =ROUND(SUM(J40:J43),2) -> 14.54
B45: Equipos
B46: HERRAMIENTAS MANUALES | F46: %mo | H46: 3 | I46: =J38 -> 113.78 | J46: =ROUND(H46%*I46,2) -> 3.41 | K46: 37
...

Sheet ELECTRICAS
G2: Unidad | H2: Metrado | I2: C.U | J2: Parcial | K2: Total
A3: 5 | B3: INSTALACIONES ELECTRICAS | K3: =J4+J9 -> 266619.99
A4: 5.01 | B4: SALIDAS | J4: =SUM(J5:J8) -> 181212.1
A5: 05.01.01 | B5: SALIDAS PARA ALUMBRADO, TOMACORRIENTES, FUERZA Y SEÑALES DÉBILES | G5: pto | H5: =ROUNDUP(SUM(BIBLIOTECA:INGRESO!G59),0) -> 449 | I5: =ROUND('APUS ELECTRICAS'!J5,2) -> 121.05 | J5: =ROUND(H5*I5,2) -> 54351.45
A6: 05.01.02 | B6: SALIDAS PARA TOMACORRIENTES | G6: pto | H6: =ROUNDUP(SUM(BIBLIOTECA:INGRESO!G60),0) -> 449 | I6: =ROUND('APUS ELECTRICAS'!J26,2) -> 163.75 | J6: =ROUND(H6*I6,2) -> 73523.75
A7: 05.01.03 | B7: SALIDAS PARA FUERZA Y SEÑALES DÉBILES | G7: pto | H7: =ROUNDUP(SUM(BIBLIOTECA:INGRESO!G61),0) -> 449 | I7: =ROUND('APUS ELECTRICAS'!J48,2) -> 118.3 | J7: =ROUND(H7*I7,2) -> 53116.7
A8: 05.01.04 | B8: SALIDAS TRIFÁSICAS | G8: pto | H8: =ROUNDUP(SUM(BIBLIOTECA:INGRESO!G62),0) -> 30 | I8: =ROUND('APUS ELECTRICAS'!J66,2) -> 7.34 | J8: =ROUND(H8*I8,2) -> 220.2
A9: 5.02 | B9: LÁMPARAS | J9: =SUM(J10:J15) -> 85407.89
A10: 05.02.01 | B10: ARTEFACTO DE ILUMINACIÓN P = 63 W L = 8000 LM | G10: und | H10: =ROUNDUP(SUM(BIBLIOTECA:INGRESO!G64),0) -> 141 | I10: =ROUND('APUS ELECTRICAS'!J74,2) -> 396.15 | J10: =ROUND(H10*I10,2) -> 55857.15
A11: 05.02.02 | B11: INSTALACIÓN DE ARTEFACTO DE ILUMINACIÓN, P=63 W L=8000 LM | G11: und | H11: =ROUNDUP(SUM(BIBLIOTECA:INGRESO!G65),0) -> 141 | I11: =ROUND('APUS ELECTRICAS'!J88,2) -> 125.39 | J11: =ROUND(H11*I11,2) -> 17679.99
A12: 05.02.03 | B12: PROYECTOR Y PANTALLA | G12: und | H12: =ROUNDUP(SUM(BIBLIOTECA:INGRESO!G66),0) -> 11 | I12: =ROUND('APUS ELECTRICAS'!J106,2) -> 143.11 | J12: =ROUND(H12*I12,2) -> 1574.21
A13: 05.02.04 | B13: EXTRACTORES DE AIRE | G13: und | H13: =ROUNDUP(SUM(BIBLIOTECA:INGRESO!G67),0) -> 3 | I13: =ROUND('APUS ELECTRICAS'!J114,2) -> 86.82 | J13: =ROUND(H13*I13,2) -> 260.46
A14: 05.02.05 | B14: SISTEMA DE BAJA TENSIÓN | G14: und | H14: =ROUND('Datos iniciales '!B69,2) -> 106 | I14: =ROUND('APUS ELECTRICAS'!J133,2) -> 87.34 | J14: =ROUND(H14*I14,2) -> 9258.04
A15: 05.02.06 | B15: SISTEMA DE MEDIA TENSIÓN | G15: und | H15: =ROUND('Datos iniciales '!B69,2) -> 106 | I15: =ROUND('APUS ELECTRICAS'!J140,2) -> 7.34 | J15: =ROUND(H15*I15,2) -> 778.04

Sheet APUS ELECTRICAS
A4: Partida | B4: =ELECTRICAS!A5 -> 05.01.01 | C4: SALIDAS PARA ALUMBRADO
A5: Rendimiento m2/día | B5: pto/dia | C5: M.O | D5: 5 | E5: EQ | F5: =D5 -> 5 | G5: Costo unitario directo | I5: pto | J5: =J11+J20+J23 -> 121.05
A6: Código | B6: Descripción Recurso | F6: Unidad | G6: Cuadrilla | H6: Cantidad | I6: Precio (S/.) | J6: Parcial (S/.)
B7: Mano de Obra
B8: CAPATAZ | F8: hh | G8: 0.1 | H8: =ROUND(G8*8/$D$5,4) -> 0.16 | I8: 34.73 | J8: =ROUND(H8*I8,2) -> 5.56 | K8: 47
B9: OPERARIO | F9: hh | G9: 1 | H9: =ROUND(G9*8/$D$5,4) -> 1.6 | I9: 28.94 | J9: =ROUND(H9*I9,2) -> 46.3 | K9: 47
B10: PEON | F10: hh | G10: 1 | H10: =ROUND(G10*8/$D$5,4) -> 1.6 | I10: 20.51 | J10: =ROUND(H10*I10,2) -> 32.82 | K10: 47
J11: =ROUND(SUM(J8:J10),2) -> 84.68
B12: Materiales
B13: TUBERÍA ELÉCTRICA SAP GRIS 3/4" X3 METROS NICOLL | F13: und | H13: 1.5 | I13: 10.68 | J13: =ROUND(H13*I13,2) -> 16.02 | K13: 72
B14: CURVA SAP 3/4" NICOLL | F14: und | H14: 3 | I14: 2.12 | J14: =ROUND(H14*I14,2) -> 6.36 | K14: 72
B15: UNIÓN SAP 3/4" NICOLL | F15: und | H15: 1 | I15: 0.68 | J15: =ROUND(H15*I15,2) -> 0.68 | K15: 72
B16: CONEXIÓN A CAJA PVC ELÉCTRICA SAP 3/4" | F16: und | H16: 1 | I16: 0.51 | J16: =ROUND(H16*I16,2) -> 0.51 | K16: 39
B17: CINTA AISLANTE ELÉCTRICA | F17: und | H17: 0.1 | I17: 4.66 | J17: =ROUND(H17*I17,2) -> 0.47 | K17: 30
B18: CAJA DE PASE OCTOGONAL F.G. PESADA 4" | F18: und | H18: 1 | I18: 1.69 | J18: =ROUND(H18*I18,2) -> 1.69 | K18: 39
B19: ALAMBRE TW 14 AWG | F19: m | H19: 9 | I19: 0.9 | J19: =ROUND(H19*I19,2) -> 8.1 | K19: 2
J20: =ROUND(SUM(J13:J19),2) -> 33.83
B21: Equipos
B22: HERRAMIENTAS MANUALES | F22: %mo | H22: 3 | I22: =J11 -> 84.68 | J22: =ROUND(H22%*I22,2) -> 2.54 | K22: 37
J23: =ROUND(SUM(J22),2) -> 2.54
A25: Partida | B25: =ELECTRICAS!A6 -> 05.01.02 | C25: SALIDAS PARA TOMACORRIENTE
A26: Rendimiento m2/día | B26: pto/dia | C26: M.O | D26: 4 | E26: EQ | F26: =D26 -> 4 | G26: Costo unitario directo | I26: pto | J26: =J32+J42+J45 -> 163.75
A27: Código | B27: Descripción Recurso | F27: Unidad | G27: Cuadrilla | H27: Cantidad | I27: Precio (S/.) | J27: Parcial (S/.)
B28: Mano de Obra
B29: CAPATAZ | F29: hh | G29: 0.1 | H29: =ROUND(G29*8/$D$26,4) -> 0.2 | I29: 34.73 | J29: =ROUND(H29*I29,2) -> 6.95 | K29: 47
B30: OPERARIO | F30: hh | G30: 1 | H30: =ROUND(G30*8/$D$26,4) -> 2 | I30: 28.94 | J30: =ROUND(H30*I30,2) -> 57.88 | K30: 47
B31: PEON | F31: hh | G31: 1 | H31: =ROUND(G31*8/$D$26,4) -> 2 | I31: 20.51 | J31: =ROUND(H31*I31,2) -> 41.02 | K31: 47
J32: =ROUND(SUM(J29:J31),2) -> 105.85
B33: Materiales
B34: TUBERÍA ELÉCTRICA SAP GRIS 3/4" X3 METROS NICOLL | F34: und | H34: 1.5 | I34: 10.68 | J34: =ROUND(H34*I34,2) -> 16.02 | K34: 72
B35: CURVA SAP 3/4" NICOLL | F35: und | H35: 3 | I35: 2.12 | J35: =ROUND(H35*I35,2) -> 6.36 | K35: 72
B36: UNIÓN SAP 3/4" NICOLL | F36: und | H36: 1 | I36: 0.68 | J36: =ROUND(H36*I36,2) -> 0.68 | K36: 72
B37: CONEXIÓN A CAJA PVC ELÉCTRICA SAP 3/4" | F37: und | H37: 2 | I37: 0.51 | J37: =ROUND(H37*I37,2) -> 1.02 | K37: 39
B38: CINTA AISLANTE ELÉCTRICA | F38: und | H38: 0.1 | I38: 4.66 | J38: =ROUND(H38*I38,2) -> 0.47 | K38: 30
B39: TOMACORRIENTE DOBLE UNIVERSAL 2 POLOS 10A 250VAC | F39: und | H39: 1.05 | I39: 16.02 | J39: =ROUND(H39*I39,2) -> 16.82 | K39: 11
B40: CAJA DE PASE RECTANGULAR F.G. PESADA 50 x100 mm | F40: und | H40: 1.05 | I40: 5 | J40: =ROUND(H40*I40,2) -> 5.25 | K40: 39
B41: ALAMBRE TW 14 AWG | F41: m | H41: 9 | I41: 0.9 | J41: =ROUND(H41*I41,2) -> 8.1 | K41: 2
J42: =ROUND(SUM(J34:J41),2) -> 54.72
B43: Equipos
B44: HERRAMIENTAS MANUALES | F44: %mo | H44: 3 | I44: =J32 -> 105.85 | J44: =ROUND(H44%*I44,2) -> 3.18 | K44: 37
...

Sheet COMUNICACIONES
G2: Unidad | H2: Metrado | I2: C.U | J2: Parcial | K2: Total
A3: 6 | B3: INSTALACIONES COMUNICACIONES | K3: =J4+J16+J32+J36+J39 -> 141077.34
A4: 6.01 | B4: CANALIZACIÓN, CONDUCTOS Y/O TUBERÍAS | J4: =SUM(J5:J15) -> 21248.12
A5: 06.01.01 | B5: INSTALACION DE PUNTOS DE RED EN PISO | G5: und | H5: =ROUNDUP(SUM(BIBLIOTECA:INGRESO!G72),0) -> 26 | I5: =ROUND('APUS COMUNICACIONES'!J5,2) -> 279.85 | J5: =ROUND(H5*I5,2) -> 7276.1
A6: 06.01.02 | B6: INSTALACION DE PUNTOS DE RED EN PARED | G6: und | H6: =ROUNDUP(SUM(BIBLIOTECA:INGRESO!G73),0) -> 26 | I6: =ROUND('APUS COMUNICACIONES'!J23,2) -> 95.84 | J6: =ROUND(H6*I6,2) -> 2491.84
A7: 06.01.03 | B7: INSTALACION DE PUNTOS DE RED EN CIELO RASO | G7: und | H7: =ROUNDUP(SUM(BIBLIOTECA:INGRESO!G74),0) -> 26 | I7: =ROUND('APUS COMUNICACIONES'!J41,2) -> 95.84 | J7: =ROUND(H7*I7,2) -> 2491.84
A8: 06.01.04 | B8: TUBERIA PVC-P ELÉCTRICA Ø50mm, NTP 339.006 | G8: m | H8: =ROUND(SUM(BIBLIOTECA:INGRESO!G75),2) -> 1.56 | I8: =ROUND('APUS COMUNICACIONES'!J59,2) -> 26.42 | J8: =ROUND(H8*I8,2) -> 41.22
A9: 06.01.05 | B9: TUBERIA PVC-P ELÉCTRICA Ø40mm, NTP 339.006 | G9: m | H9: =ROUND(SUM(BIBLIOTECA:INGRESO!G76),2) -> 35.36 | I9: =ROUND('APUS COMUNICACIONES'!J77,2) -> 25.01 | J9: =ROUND(H9*I9,2) -> 884.35
